<?xml version="1.0" ?>
<!-- =================================================================================== -->
<!-- |    This document was autogenerated by xacro from /root/ros_ws/src/explab_2nd/urdf/detectiBot.xacro | -->
<!-- |    EDITING THIS FILE BY HAND IS NOT RECOMMENDED                                 | -->
<!-- =================================================================================== -->
<robot xmlns:xacro="http://www.ros.org/wiki/xacro" name="detectiBot">
    <!-- =================================================================================== -->
    <!-- |                                 detectiBot model                                | -->
    <!-- |                             Experimental robotics lab                           | -->
    <!-- =================================================================================== -->
    <!-- ==================================== Xacro include ============================================ -->
    <material name="neongreen">
        <color rgba="0.047058823529411764 1.0 0.047058823529411764 1.0" />
    </material>
    <material name="black">
        <color rgba="0.0 0.0 0.0 1.0" />
    </material>
    <material name="acidgreen">
        <color rgba="0.5607843137254902 0.996078431372549 0.03529411764705882 1.0" />
    </material>
    <material name="blue">
        <color rgba="0.203125 0.23828125 0.28515625 1.0" />
    </material>
    <material name="green">
        <color rgba="0.0 0.8 0.0 1.0" />
    </material>
    <material name="ocre">
        <color rgba="0.7764705882352941 0.611764705882353 0.01568627450980392 1.0" />
    </material>
    <material name="grey">
        <color rgba="0.2 0.2 0.2 1.0" />
    </material>
    <material name="bruise">
        <color rgba="0.49411764705882355 0.25098039215686274 0.44313725490196076 1.0" />
    </material>
    <material name="orange">
        <color rgba="1.0 0.423529411765 0.0392156862745 1.0" />
    </material>
    <material name="brown">
        <color rgba="0.870588235294 0.811764705882 0.764705882353 1.0" />
    </material>
    <material name="burgundy">
        <color rgba="0.3803921568627451 0.0 0.13725490196078433 1.0" />
    </material>
    <material name="dusk">
        <color rgba="0.3058823529411765 0.32941176470588235 0.5058823529411764 1.0" />
    </material>
    <material name="red">
        <color rgba="0.80078125 0.12890625 0.1328125 1.0" />
    </material>
    <material name="white">
        <color rgba="1.0 1.0 1.0 1.0" />
    </material>
    <!-- ==================================== gazebo/material  ========================================= -->
    <!-- ======================================== Joint  =============================================== -->
    <!-- ========================================= FB  ================================================= -->
    <gazebo reference="base_link">
        <material>Gazebo/Orange</material>
    </gazebo>
    <gazebo reference="link_left_wheel">
        <material>Gazebo/Blue</material>
    </gazebo>
    <gazebo reference="link_right_wheel">
        <material>Gazebo/Blue</material>
    </gazebo>
    <gazebo reference="arm_base_link">
        <material>Gazebo/Red</material>
    </gazebo>
    <gazebo reference="arm_link_01">
        <material>Gazebo/Red</material>
    </gazebo>
    <gazebo reference="arm_link_02">
        <material>Gazebo/Red</material>
    </gazebo>
    <gazebo reference="arm_link_03">
        <material>Gazebo/Red</material>
    </gazebo>
    <gazebo reference="arm_link_03">
        <material>Gazebo/Red</material>
    </gazebo>
    <gazebo reference="arm_link_04">
        <material>Gazebo/Red</material>
    </gazebo>
    <gazebo reference="right_grip_link">
        <material>Gazebo/White</material>
    </gazebo>
    <gazebo reference="left_grip_link">
        <material>Gazebo/White</material>
    </gazebo>
    <!-- ========================================= FB  ================================================= -->
    <gazebo reference="arm_joint_02">
        <provideFeedback>true</provideFeedback>
    </gazebo>
    <!-- ======================================  Plugins  ============================================== -->
    <gazebo>
        <plugin filename="libgazebo_ros_ft_sensor.so" name="ft_sensor">
            <updateRate>100.0</updateRate>
            <topicName>ft_sensor_topic</topicName>
            <jointName>arm_joint_02</jointName>
        </plugin>
    </gazebo>
    <gazebo>
        <plugin filename="libgazebo_ros_diff_drive.so" name="differential_drive_controller">
            <legacyMode>true</legacyMode>
            <alwaysOn>true</alwaysOn>
            <updateRate>20</updateRate>
            <leftJoint>joint_right_wheel</leftJoint>
            <rightJoint>joint_left_wheel</rightJoint>
            <wheelSeparation>0.3</wheelSeparation>
            <wheelDiameter>0.2</wheelDiameter>
            <torque>0.1</torque>
            <commandTopic>cmd_vel</commandTopic>
            <odometryTopic>odom</odometryTopic>
            <odometryFrame>odom</odometryFrame>
            <robotBaseFrame>base_link</robotBaseFrame>
            <rosDebugLevel>na</rosDebugLevel>
            <publishWheelTF>true</publishWheelTF>
            <publishWheelJointState>true</publishWheelJointState>
            <wheelAcceleration>0</wheelAcceleration>
            <wheelTorque>5</wheelTorque>
            <odometrySource>1</odometrySource>
            <publishTf>1</publishTf>
        </plugin>
    </gazebo>
    <gazebo reference="laser">
        <sensor name="head_hokuyo_sensor" type="ray">
            <pose>0 0 0 0 0 0</pose>
            <visualize>false</visualize>
            <update_rate>20</update_rate>
            <ray>
                <scan>
                    <horizontal>
                        <samples>720</samples>
                        <resolution>1</resolution>
                        <min_angle>-1.570796</min_angle>
                        <max_angle>1.570796</max_angle>
                    </horizontal>
                </scan>
                <range>
                    <min>0.10</min>
                    <max>10.0</max>
                    <resolution>0.01</resolution>
                </range>
                <noise>
                    <type>gaussian</type>
                    <mean>0.0</mean>
                    <stddev>0.01</stddev>
                </noise>
            </ray>
            <plugin filename="libgazebo_ros_laser.so" name="gazebo_ros_head_hokuyo_controller">
                <topicName>/scan</topicName>
                <frameName>laser</frameName>
            </plugin>
        </sensor>
    </gazebo>
    <!-- ===================================== ROS_CONTROL  ============================================ -->
    <gazebo>
        <plugin filename="libgazebo_ros_control.so" name="gazebo_ros_control">
            <robotNamespace>m2wr</robotNamespace>
            <robotSimType>gazebo_ros_control/DefaultRobotHWSim</robotSimType>
            <legacyModeNS>true</legacyModeNS>
        </plugin>
    </gazebo>
    <!-- ================================== Properties' list ============================================ -->
    <!-- ======================== All units in m-kg-s-radians unit system =============================== -->
    <!-- math and conversion  -->
    <!-- mass  -->
    <!-- lenght -->
    <!-- ================================== Xacro definitions ========================================== -->
    <!-- ======================================== Link  ================================================ -->
    <link name="base_link">
        <!-- pose and inertial -->
        <pose>0 0 0.1 0 0 0</pose>
        
<inertial>
            <mass value="0.5" />
            <origin rpy="0 0 0" xyz="0 0 0.1" />
            <inertia ixx="0.0395416666667" ixy="0" ixz="0" iyy="0.106208333333" iyz="0" izz="0.106208333333" />
        </inertial>

        <!-- chassis collision -->
        <collision name="collision_chassis">
            <geometry>
                <box size="0.5 0.3 0.07" />
            </geometry>
        </collision>
        <visual>
            <origin rpy="0 0 0" xyz="0 0 0" />
            <geometry>
                <box size="0.5 0.3 0.07" />
            </geometry>
            <material name="blue" />
        </visual>
        <!-- caster front collision -->
        <collision name="caster_front_collision">
            <origin rpy=" 0 0 0" xyz="0.35 0 -0.05" />
            <geometry>
                <sphere radius="0.05" />
            </geometry>
            <surface>
                <friction>
                    <ode>
                        <mu>0</mu>
                        <mu2>0</mu2>
                        <slip1>1.0</slip1>
                        <slip2>1.0</slip2>
                    </ode>
                </friction>
            </surface>
        </collision>
        <visual name="caster_front_visual">
            <origin rpy=" 0 0 0" xyz="0.2 0 -0.05" />
            <geometry>
                <sphere radius="0.05" />
            </geometry>
        </visual>
    </link>
    <!-- ==================================== Create wheels ============================================ -->
    <link name="link_right_wheel">
        
<inertial>
            <mass value="0.2" />
            <origin rpy="0 1.5707 1.5707" xyz="0 0 0" />
            <inertia ixx="0.000526666666667" ixy="0" ixz="0" iyy="0.000526666666667" iyz="0" izz="0.001" />
        </inertial>

        <collision name="link_right_wheel_collision">
            <origin rpy="0 1.5707 1.5707" xyz="0 0 0" />
            <geometry>
                <cylinder length="0.04" radius="0.1" />
            </geometry>
        </collision>
        <visual name="link_right_wheel_visual">
            <origin rpy="0 1.5707 1.5707" xyz="0 0 0" />
            <geometry>
                <cylinder length="0.04" radius="0.1" />
            </geometry>
        </visual>
    </link>
    <link name="link_left_wheel">
        
<inertial>
            <mass value="0.2" />
            <origin rpy="0 1.5707 1.5707" xyz="0 0 0" />
            <inertia ixx="0.000526666666667" ixy="0" ixz="0" iyy="0.000526666666667" iyz="0" izz="0.001" />
        </inertial>

        <collision name="link_right_wheel_collision">
            <origin rpy="0 1.5707 1.5707" xyz="0 0 0" />
            <geometry>
                <cylinder length="0.04" radius="0.1" />
            </geometry>
        </collision>
        <visual name="link_left_wheel_visual">
            <origin rpy="0 1.5707 1.5707" xyz="0 0 0" />
            <geometry>
                <cylinder length="0.04" radius="0.1" />
            </geometry>
        </visual>
    </link>
    <joint name="joint_right_wheel" type="continuous">
        <origin rpy="0 0 0" xyz="-0.05 0.15 0" />
        <child link="link_right_wheel" />
        <parent link="base_link" />
        <axis rpy="0 0 0" xyz="0 1 0" />
        <limit effort="10000" velocity="1000" />
        <joint_properties damping="1.0" friction="1.0" />
    </joint>
    <joint name="joint_left_wheel" type="continuous">
        <origin rpy="0 0 0" xyz="-0.05 -0.15 0" />
        <child link="link_left_wheel" />
        <parent link="base_link" />
        <axis rpy="0 0 0" xyz="0 1 0" />
        <limit effort="10000" velocity="1000" />
        <joint_properties damping="1.0" friction="1.0" />
    </joint>
    <!-- ======================================== Link  ================================================ -->
    <link name="laser">
        
<inertial>
            <origin rpy="0 0 0" xyz="0 0 0" />
            <mass value="1" />
            <inertia ixx="0.0014583333333333334" ixy="0" ixz="0" iyy="0.0014583333333333334" iyz="0" izz="0.0012500000000000002" />
        </inertial>

        <visual>
            <origin rpy="0 0 0" xyz="0 0 0" />
            <geometry>
                <cylinder length="0.1" radius="0.05" />
            </geometry>
            <material name="white" />
        </visual>
        <collision>
            <origin rpy="0 0 0" xyz="0 0 0" />
            <geometry>
                <cylinder length="0.1" radius="0.05" />
            </geometry>
        </collision>
    </link>
    <!-- ======================================== Joint  =============================================== -->
    <joint name="joint_laser" type="fixed">
        <origin rpy="0 0 0" xyz="0.15 0 0.05" />
        <parent link="base_link" />
        <child link="laser" />
    </joint>
    <!-- ======================================== Link  ================================================ -->

   <!-- camera -->
  <gazebo reference="camera_link">
    <sensor type="camera" name="camera1">
      <update_rate>30.0</update_rate>
      <camera name="head">
        <horizontal_fov>1.3962634</horizontal_fov>
        <image>
          <width>800</width>
          <height>800</height>
          <format>R8G8B8</format>
        </image>
        <clip>
          <near>0.02</near>
          <far>300</far>
        </clip>
		<noise>
          <type>gaussian</type>
          <mean>0.0</mean>
          <stddev>0.007</stddev>
        </noise>
      </camera>
      <plugin name="camera_controller" filename="libgazebo_ros_camera.so">
        <alwaysOn>true</alwaysOn>
        <updateRate>0.0</updateRate>
        <cameraName>robot/camera1</cameraName>
        <imageTopicName>image_raw</imageTopicName>
        <cameraInfoTopicName>camera_info</cameraInfoTopicName>
        <frameName>camera_link</frameName>
        <hackBaseline>0.07</hackBaseline>
        <distortionK1>0.0</distortionK1>
        <distortionK2>0.0</distortionK2>
        <distortionK3>0.0</distortionK3>
        <distortionT1>0.0</distortionT1>
        <distortionT2>0.0</distortionT2>
      </plugin>
    </sensor>
  </gazebo> 
  
  	<link name="camera_link">
	    <collision>
	      <origin xyz="0 0 0.025" rpy="0 0 0"/>
	    <geometry>
		<box size="0.05 0.05 0.05"/>
	    </geometry> -->
	    </collision>
	    <!-- <visual>
	      <origin xyz="0 0 0.025" rpy="0 0 0"/>
	      <geometry>
		<box size="0.05 0.05 0.05"/>
	      </geometry>
	      <material name="red">
		<color rgba="1 0 0 1"/>
	      </material>
	    </visual>-->
	    <inertial>
	      <mass value="1e-5" />
	      <origin xyz="0 0 0" rpy="0 0 0"/>
	      <inertia ixx="1e-6" ixy="0" ixz="0" iyy="1e-6" iyz="0" izz="1e-6" />
	    </inertial> 
  </link>
  
  <joint name="camera_joint" type="fixed">
	    <axis xyz="0 1 0" />
	    <origin xyz="0.23 0 0.25" rpy="0 0 0"/>
	    <parent link="base_link"/>
	    <child link="camera_link"/> 
	 </joint>


</robot>
